<sdf version='1.7'>
  <model name='anymal_d'>
    <link name='base'>
      <inertial>
        <pose>-0.016448 0.000682 -0.011954 0 -0 0</pose>
        <mass>26.3631</mass>
        <inertia>
          <ixx>0.251773</ixx>
          <ixy>0.00508377</ixy>
          <ixz>0.0238682</ixz>
          <iyy>1.46787</iyy>
          <iyz>0.000582816</iyz>
          <izz>1.53396</izz>
        </inertia>
      </inertial>
      <collision name='base_collision'>
        <pose>0 0 0.016 0 -0 0</pose>
        <geometry>
          <box>
            <size>0.894 0.1615 0.256</size>
          </box>
        </geometry>
      </collision>
      <collision name='base_collision_1'>
        <pose>0.2353 0.08075 0 0 1.5708 0</pose>
        <geometry>
          <cylinder>
            <length>0.1482</length>
            <radius>0.089</radius>
          </cylinder>
        </geometry>
      </collision>
      <collision name='base_collision_2'>
        <pose>0.2353 -0.08075 0 0 1.5708 0</pose>
        <geometry>
          <cylinder>
            <length>0.1482</length>
            <radius>0.089</radius>
          </cylinder>
        </geometry>
      </collision>
      <collision name='base_collision_3'>
        <pose>-0.2353 0.08075 0 0 1.5708 0</pose>
        <geometry>
          <cylinder>
            <length>0.1482</length>
            <radius>0.089</radius>
          </cylinder>
        </geometry>
      </collision>
      <collision name='base_collision_4'>
        <pose>-0.2353 -0.08075 0 0 1.5708 0</pose>
        <geometry>
          <cylinder>
            <length>0.1482</length>
            <radius>0.089</radius>
          </cylinder>
        </geometry>
      </collision>
      <collision name='base_fixed_joint_lump__lidar_collision_5'>
        <pose>-0.31 0 0.1585 0 -0 3.14159</pose>
        <geometry>
          <cylinder>
            <length>0.1355</length>
            <radius>0.07</radius>
          </cylinder>
        </geometry>
      </collision>
      <visual name='base_visual'>
        <pose>0 0 0 0 -0 0</pose>
        <geometry>
          <mesh>
            <scale>1 1 1</scale>
            <uri>model://ocs2_robotic_assets/resources/anymal_d/meshes/base.dae</uri>
          </mesh>
        </geometry>
      </visual>
      <visual name='base_fixed_joint_lump__LF_HAA_drive_visual_1'>
        <pose>0.304 0.109 0 0 -0 0</pose>
        <geometry>
          <mesh>
            <scale>1 1 1</scale>
            <uri>model://ocs2_robotic_assets/resources/anymal_d/meshes/drive.dae</uri>
          </mesh>
        </geometry>
      </visual>
      <visual name='base_fixed_joint_lump__LH_HAA_drive_visual_2'>
        <pose>-0.304 0.109 0 0 0 -3.14159</pose>
        <geometry>
          <mesh>
            <scale>1 1 1</scale>
            <uri>model://ocs2_robotic_assets/resources/anymal_d/meshes/drive.dae</uri>
          </mesh>
        </geometry>
      </visual>
      <visual name='base_fixed_joint_lump__RF_HAA_drive_visual_3'>
        <pose>0.304 -0.109 0 0 -0 0</pose>
        <geometry>
          <mesh>
            <scale>1 1 1</scale>
            <uri>model://ocs2_robotic_assets/resources/anymal_d/meshes/drive.dae</uri>
          </mesh>
        </geometry>
      </visual>
      <visual name='base_fixed_joint_lump__RH_HAA_drive_visual_4'>
        <pose>-0.304 -0.109 0 0 0 -3.14159</pose>
        <geometry>
          <mesh>
            <scale>1 1 1</scale>
            <uri>model://ocs2_robotic_assets/resources/anymal_d/meshes/drive.dae</uri>
          </mesh>
        </geometry>
      </visual>
      <visual name='base_fixed_joint_lump__battery_visual_5'>
        <pose>0 0 0 0 -0 0</pose>
        <geometry>
          <mesh>
            <scale>1 1 1</scale>
            <uri>model://ocs2_robotic_assets/resources/anymal_d/meshes/battery.dae</uri>
          </mesh>
        </geometry>
      </visual>
      <visual name='base_fixed_joint_lump__bottom_shell_visual_6'>
        <pose>0 0 0 0 -0 0</pose>
        <geometry>
          <mesh>
            <scale>1 1 1</scale>
            <uri>model://ocs2_robotic_assets/resources/anymal_d/meshes/bottom_shell.dae</uri>
          </mesh>
        </geometry>
      </visual>
      <visual name='base_fixed_joint_lump__face_shell_front_visual_7'>
        <pose>0.4087 0 0.0205 0 -0 0</pose>
        <geometry>
          <mesh>
            <scale>1 1 1</scale>
            <uri>model://ocs2_robotic_assets/resources/anymal_d/meshes/face_shell.dae</uri>
          </mesh>
        </geometry>
      </visual>
      <visual name='base_fixed_joint_lump__face_shell_rear_visual_8'>
        <pose>-0.4087 0 0.0205 0 -0 3.14159</pose>
        <geometry>
          <mesh>
            <scale>1 1 1</scale>
            <uri>model://ocs2_robotic_assets/resources/anymal_d/meshes/face_shell.dae</uri>
          </mesh>
        </geometry>
      </visual>
      <visual name='base_fixed_joint_lump__docking_socket_visual_9'>
        <pose>0.26132 0 -0.06205 0 -0 0</pose>
        <geometry>
          <mesh>
            <scale>1 1 1</scale>
            <uri>model://ocs2_robotic_assets/resources/anymal_d/meshes/docking_socket.dae</uri>
          </mesh>
        </geometry>
      </visual>
      <visual name='base_fixed_joint_lump__lidar_visual_10'>
        <pose>-0.31 0 0.1585 0 -0 3.14159</pose>
        <geometry>
          <mesh>
            <scale>1 1 1</scale>
            <uri>model://ocs2_robotic_assets/resources/anymal_d/meshes/lidar.dae</uri>
          </mesh>
        </geometry>
      </visual>
      <visual name='base_fixed_joint_lump__lidar_visual_11'>
        <pose>-0.31 0 0.1585 0 -0 3.14159</pose>
        <geometry>
          <mesh>
            <scale>1 1 1</scale>
            <uri>model://ocs2_robotic_assets/resources/anymal_d/meshes/lidar_guard.dae</uri>
          </mesh>
        </geometry>
      </visual>
      <visual name='base_fixed_joint_lump__top_shell_visual_12'>
        <pose>0 0 0 0 -0 0</pose>
        <geometry>
          <mesh>
            <scale>1 1 1</scale>
            <uri>model://ocs2_robotic_assets/resources/anymal_d/meshes/top_shell.dae</uri>
          </mesh>
        </geometry>
      </visual>
    </link>
    <joint name='LF_HAA' type='revolute'>
      <pose relative_to='base'>0.304 0.109 0 0 -0 0</pose>
      <parent>base</parent>
      <child>LF_HIP</child>
      <axis>
        <xyz>1 0 0</xyz>
        <limit>
          <lower>-0.785398</lower>
          <upper>0.610865</upper>
          <effort>80</effort>
          <velocity>8.5</velocity>
        </limit>
        <dynamics>
          <damping>0</damping>
          <friction>0</friction>
          <spring_reference>0</spring_reference>
          <spring_stiffness>0</spring_stiffness>
        </dynamics>
      </axis>
    </joint>
    <link name='LF_HIP'>
      <pose relative_to='LF_HAA'>0 0 0 0 -0 0</pose>
      <inertial>
        <pose>0.035047 -0.001227 0 0 -0 0</pose>
        <mass>0.36586</mass>
        <inertia>
          <ixx>0.000238523</ixx>
          <ixy>3.25536e-06</ixy>
          <ixz>1.268e-08</ixz>
          <iyy>0.000558246</iyy>
          <iyz>1.811e-08</iyz>
          <izz>0.000443321</izz>
        </inertia>
      </inertial>
      <visual name='LF_HIP_fixed_joint_lump__LF_hip_fixed_visual'>
        <pose>0 0 0 0 -0 0</pose>
        <geometry>
          <mesh>
            <scale>1 1 1</scale>
            <uri>model://ocs2_robotic_assets/resources/anymal_d/meshes/hip.dae</uri>
          </mesh>
        </geometry>
      </visual>
    </link>
    <joint name='LF_HFE' type='revolute'>
      <pose relative_to='LF_HIP'>0.069 0.006 0 0 0 -1.5708</pose>
      <parent>LF_HIP</parent>
      <child>LF_THIGH</child>
      <axis>
        <xyz>-1 0 0</xyz>
        <limit>
          <lower>-9.42478</lower>
          <upper>9.42478</upper>
          <effort>80</effort>
          <velocity>8.5</velocity>
        </limit>
        <dynamics>
          <damping>0</damping>
          <friction>0</friction>
          <spring_reference>0</spring_reference>
          <spring_stiffness>0</spring_stiffness>
        </dynamics>
      </axis>
    </joint>
    <link name='LF_THIGH'>
      <pose relative_to='LF_HFE'>0 0 0 0 -0 0</pose>
      <inertial>
        <pose>-0.090511 -8.8e-05 -0.140188 0 -0 0</pose>
        <mass>5.1322</mass>
        <inertia>
          <ixx>0.10488</ixx>
          <ixy>-0.00014199</ixy>
          <ixz>-0.0200595</ixz>
          <iyy>0.107959</iyy>
          <iyz>0.000403</iyz>
          <izz>0.0139329</izz>
        </inertia>
      </inertial>
      <collision name='LF_THIGH_fixed_joint_lump__LF_HFE_drive_collision'>
        <pose>-0.0595 0 0 0 1.5708 0</pose>
        <geometry>
          <cylinder>
            <length>0.119</length>
            <radius>0.05375</radius>
          </cylinder>
        </geometry>
      </collision>
      <collision name='LF_THIGH_fixed_joint_lump__LF_thigh_fixed_collision_1'>
        <pose>-0.105195 0 0 1.5708 -0 1.5708</pose>
        <geometry>
          <cylinder>
            <length>0.08313</length>
            <radius>0.07</radius>
          </cylinder>
        </geometry>
      </collision>
      <collision name='LF_THIGH_fixed_joint_lump__LF_thigh_fixed_collision_2'>
        <pose>-0.09513 0 -0.1425 0 -0 1.5708</pose>
        <geometry>
          <box>
            <size>0.093 0.063 0.285</size>
          </box>
        </geometry>
      </collision>
      <collision name='LF_THIGH_fixed_joint_lump__LF_thigh_fixed_collision_3'>
        <pose>-0.085065 0 -0.285 1.5708 -0 1.5708</pose>
        <geometry>
          <cylinder>
            <length>0.08313</length>
            <radius>0.07</radius>
          </cylinder>
        </geometry>
      </collision>
      <collision name='LF_THIGH_fixed_joint_lump__LF_KFE_drive_collision_4'>
        <pose>-0.121 0 -0.285 -3.14159 1.5708 0</pose>
        <geometry>
          <cylinder>
            <length>0.119</length>
            <radius>0.05375</radius>
          </cylinder>
        </geometry>
      </collision>
      <visual name='LF_THIGH_fixed_joint_lump__LF_HFE_drive_visual'>
        <pose>0 0 0 0 -0 0</pose>
        <geometry>
          <mesh>
            <scale>1 1 1</scale>
            <uri>model://ocs2_robotic_assets/resources/anymal_d/meshes/drive.dae</uri>
          </mesh>
        </geometry>
      </visual>
      <visual name='LF_THIGH_fixed_joint_lump__LF_thigh_fixed_visual_1'>
        <pose>0 0 0 0 -0 1.5708</pose>
        <geometry>
          <mesh>
            <scale>1 1 1</scale>
            <uri>model://ocs2_robotic_assets/resources/anymal_d/meshes/thigh.dae</uri>
          </mesh>
        </geometry>
      </visual>
      <visual name='LF_THIGH_fixed_joint_lump__LF_KFE_drive_visual_2'>
        <pose>-0.1805 0 -0.285 0 -0 3.14159</pose>
        <geometry>
          <mesh>
            <scale>1 1 1</scale>
            <uri>model://ocs2_robotic_assets/resources/anymal_d/meshes/drive.dae</uri>
          </mesh>
        </geometry>
      </visual>
    </link>
    <joint name='LF_KFE' type='revolute'>
      <pose relative_to='LF_THIGH'>-0.1805 0 -0.285 0 -0 3.14159</pose>
      <parent>LF_THIGH</parent>
      <child>LF_SHANK</child>
      <axis>
        <xyz>1 0 0</xyz>
        <limit>
          <lower>-9.42478</lower>
          <upper>9.42478</upper>
          <effort>80</effort>
          <velocity>8.5</velocity>
        </limit>
        <dynamics>
          <damping>0</damping>
          <friction>0</friction>
          <spring_reference>0</spring_reference>
          <spring_stiffness>0</spring_stiffness>
        </dynamics>
      </axis>
    </joint>
    <link name='LF_SHANK'>
      <pose relative_to='LF_KFE'>0 0 0 0 -0 0</pose>
      <inertial>
        <pose>0.008086 -0.050934 -0.090019 0 -0 0</pose>
        <mass>0.79598</mass>
        <inertia>
          <ixx>0.0189109</ixx>
          <ixy>-5.43254e-05</ixy>
          <ixz>6.22956e-05</ixz>
          <iyy>0.016665</iyy>
          <iyz>-0.00354904</iyz>
          <izz>0.00253121</izz>
        </inertia>
      </inertial>
      <collision name='LF_SHANK_fixed_joint_lump__LF_shank_fixed_collision'>
        <pose>0 0 0 1.5708 0 -1.5708</pose>
        <geometry>
          <cylinder>
            <length>0.05732</length>
            <radius>0.071</radius>
          </cylinder>
        </geometry>
      </collision>
      <collision name='LF_SHANK_fixed_joint_lump__LF_shank_fixed_collision_1'>
        <pose>0 -0.066415 0 1.5708 0 -1.5708</pose>
        <geometry>
          <box>
            <size>0.13283 0.08302 0.05732</size>
          </box>
        </geometry>
      </collision>
      <collision name='LF_SHANK_fixed_joint_lump__LF_FOOT_collision_2'>
        <pose>0.005359 -0.1 -0.164217 0 0 -1.5708</pose>
        <geometry>
          <cylinder>
            <length>0.39572</length>
            <radius>0.0175</radius>
          </cylinder>
        </geometry>
        <surface>
          <contact>
            <ode>
              <kp>1e+06</kp>
              <kd>100</kd>
            </ode>
          </contact>
          <friction>
            <ode>
              <mu>1.85</mu>
              <mu2>1.85</mu2>
            </ode>
          </friction>
        </surface>
      </collision>
      <collision name='LF_SHANK_fixed_joint_lump__LF_FOOT_collision_sensor_collision_3'>
        <pose>0.014109 -0.1 -0.362077 0 0 -1.5708</pose>
        <geometry>
          <sphere>
            <radius>0.031455</radius>
          </sphere>
        </geometry>
        <surface>
          <contact>
            <ode>
              <kp>1e+06</kp>
              <kd>100</kd>
            </ode>
          </contact>
          <friction>
            <ode>
              <mu>1.85</mu>
              <mu2>1.85</mu2>
            </ode>
          </friction>
        </surface>
      </collision>
      <visual name='LF_SHANK_fixed_joint_lump__LF_shank_fixed_visual'>
        <pose>0 0 0 0 0 -1.5708</pose>
        <geometry>
          <mesh>
            <scale>1 1 1</scale>
            <uri>model://ocs2_robotic_assets/resources/anymal_d/meshes/shank_l.dae</uri>
          </mesh>
        </geometry>
      </visual>
      <visual name='LF_SHANK_fixed_joint_lump__LF_FOOT_visual_1'>
        <pose>0.02225 -0.1 -0.39246 0 0 -1.5708</pose>
        <geometry>
          <mesh>
            <scale>1 1 1</scale>
            <uri>model://ocs2_robotic_assets/resources/anymal_d/meshes/foot.dae</uri>
          </mesh>
        </geometry>
      </visual>
      <sensor name='lf_foot_contact' type='contact'>
        <plugin name='lf_contact_plugin' filename='libContactSensor.so'/>
        <contact>
          <collision>LF_SHANK_fixed_joint_lump__LF_FOOT_collision_sensor_collision_3</collision>
          <topic>__default_topic__</topic>
        </contact>
        <pose>0.02225 -0.1 -0.39246 0 0 -1.5708</pose>
      </sensor>
    </link>
    <joint name='LH_HAA' type='revolute'>
      <pose relative_to='base'>-0.304 0.109 0 0 0 -3.14159</pose>
      <parent>base</parent>
      <child>LH_HIP</child>
      <axis>
        <xyz>-1 0 0</xyz>
        <limit>
          <lower>-0.785398</lower>
          <upper>0.610865</upper>
          <effort>80</effort>
          <velocity>8.5</velocity>
        </limit>
        <dynamics>
          <damping>0</damping>
          <friction>0</friction>
          <spring_reference>0</spring_reference>
          <spring_stiffness>0</spring_stiffness>
        </dynamics>
      </axis>
    </joint>
    <link name='LH_HIP'>
      <pose relative_to='LH_HAA'>0 0 0 0 -0 0</pose>
      <inertial>
        <pose>0.035047 0.001227 0 0 -0 0</pose>
        <mass>0.36586</mass>
        <inertia>
          <ixx>0.000238523</ixx>
          <ixy>-3.25536e-06</ixy>
          <ixz>1.268e-08</ixz>
          <iyy>0.000558246</iyy>
          <iyz>-1.811e-08</iyz>
          <izz>0.000443321</izz>
        </inertia>
      </inertial>
      <visual name='LH_HIP_fixed_joint_lump__LH_hip_fixed_visual'>
        <pose>0 0 0 -3.14159 -0 0</pose>
        <geometry>
          <mesh>
            <scale>1 1 1</scale>
            <uri>model://ocs2_robotic_assets/resources/anymal_d/meshes/hip.dae</uri>
          </mesh>
        </geometry>
      </visual>
    </link>
    <joint name='LH_HFE' type='revolute'>
      <pose relative_to='LH_HIP'>0.069 -0.006 0 0 -0 1.5708</pose>
      <parent>LH_HIP</parent>
      <child>LH_THIGH</child>
      <axis>
        <xyz>-1 0 0</xyz>
        <limit>
          <lower>-9.42478</lower>
          <upper>9.42478</upper>
          <effort>80</effort>
          <velocity>8.5</velocity>
        </limit>
        <dynamics>
          <damping>0</damping>
          <friction>0</friction>
          <spring_reference>0</spring_reference>
          <spring_stiffness>0</spring_stiffness>
        </dynamics>
      </axis>
    </joint>
    <link name='LH_THIGH'>
      <pose relative_to='LH_HFE'>0 0 0 0 -0 0</pose>
      <inertial>
        <pose>-0.090511 8.8e-05 -0.140188 0 -0 0</pose>
        <mass>5.1322</mass>
        <inertia>
          <ixx>0.10488</ixx>
          <ixy>0.000281268</ixy>
          <ixz>-0.0200595</ixz>
          <iyy>0.107959</iyy>
          <iyz>-0.000242195</iyz>
          <izz>0.0139329</izz>
        </inertia>
      </inertial>
      <collision name='LH_THIGH_fixed_joint_lump__LH_HFE_drive_collision'>
        <pose>-0.0595 0 0 0 1.5708 0</pose>
        <geometry>
          <cylinder>
            <length>0.119</length>
            <radius>0.05375</radius>
          </cylinder>
        </geometry>
      </collision>
      <collision name='LH_THIGH_fixed_joint_lump__LH_thigh_fixed_collision_1'>
        <pose>-0.105195 0 0 1.5708 -0 1.5708</pose>
        <geometry>
          <cylinder>
            <length>0.08313</length>
            <radius>0.07</radius>
          </cylinder>
        </geometry>
      </collision>
      <collision name='LH_THIGH_fixed_joint_lump__LH_thigh_fixed_collision_2'>
        <pose>-0.09513 0 -0.1425 0 -0 1.5708</pose>
        <geometry>
          <box>
            <size>0.093 0.063 0.285</size>
          </box>
        </geometry>
      </collision>
      <collision name='LH_THIGH_fixed_joint_lump__LH_thigh_fixed_collision_3'>
        <pose>-0.085065 0 -0.285 1.5708 -0 1.5708</pose>
        <geometry>
          <cylinder>
            <length>0.08313</length>
            <radius>0.07</radius>
          </cylinder>
        </geometry>
      </collision>
      <collision name='LH_THIGH_fixed_joint_lump__LH_KFE_drive_collision_4'>
        <pose>-0.121 0 -0.285 -3.14159 1.5708 0</pose>
        <geometry>
          <cylinder>
            <length>0.119</length>
            <radius>0.05375</radius>
          </cylinder>
        </geometry>
      </collision>
      <visual name='LH_THIGH_fixed_joint_lump__LH_HFE_drive_visual'>
        <pose>0 0 0 0 -0 0</pose>
        <geometry>
          <mesh>
            <scale>1 1 1</scale>
            <uri>model://ocs2_robotic_assets/resources/anymal_d/meshes/drive.dae</uri>
          </mesh>
        </geometry>
      </visual>
      <visual name='LH_THIGH_fixed_joint_lump__LH_thigh_fixed_visual_1'>
        <pose>0 0 0 0 -0 1.5708</pose>
        <geometry>
          <mesh>
            <scale>1 1 1</scale>
            <uri>model://ocs2_robotic_assets/resources/anymal_d/meshes/thigh.dae</uri>
          </mesh>
        </geometry>
      </visual>
      <visual name='LH_THIGH_fixed_joint_lump__LH_KFE_drive_visual_2'>
        <pose>-0.1805 0 -0.285 0 -0 3.14159</pose>
        <geometry>
          <mesh>
            <scale>1 1 1</scale>
            <uri>model://ocs2_robotic_assets/resources/anymal_d/meshes/drive.dae</uri>
          </mesh>
        </geometry>
      </visual>
    </link>
    <joint name='LH_KFE' type='revolute'>
      <pose relative_to='LH_THIGH'>-0.1805 0 -0.285 0 -0 3.14159</pose>
      <parent>LH_THIGH</parent>
      <child>LH_SHANK</child>
      <axis>
        <xyz>1 0 0</xyz>
        <limit>
          <lower>-9.42478</lower>
          <upper>9.42478</upper>
          <effort>80</effort>
          <velocity>8.5</velocity>
        </limit>
        <dynamics>
          <damping>0</damping>
          <friction>0</friction>
          <spring_reference>0</spring_reference>
          <spring_stiffness>0</spring_stiffness>
        </dynamics>
      </axis>
    </joint>
    <link name='LH_SHANK'>
      <pose relative_to='LH_KFE'>0 0 0 0 -0 0</pose>
      <inertial>
        <pose>0.008086 0.050934 -0.090019 0 -0 0</pose>
        <mass>0.79598</mass>
        <inertia>
          <ixx>0.0189109</ixx>
          <ixy>5.43254e-05</ixy>
          <ixz>6.22956e-05</ixz>
          <iyy>0.016665</iyy>
          <iyz>0.00354904</iyz>
          <izz>0.00253121</izz>
        </inertia>
      </inertial>
      <collision name='LH_SHANK_fixed_joint_lump__LH_shank_fixed_collision'>
        <pose>0 0 0 1.5708 0 -1.5708</pose>
        <geometry>
          <cylinder>
            <length>0.05732</length>
            <radius>0.071</radius>
          </cylinder>
        </geometry>
      </collision>
      <collision name='LH_SHANK_fixed_joint_lump__LH_shank_fixed_collision_1'>
        <pose>-0 0.066415 0 1.5708 0 -1.5708</pose>
        <geometry>
          <box>
            <size>0.13283 0.08302 0.05732</size>
          </box>
        </geometry>
      </collision>
      <collision name='LH_SHANK_fixed_joint_lump__LH_FOOT_collision_2'>
        <pose>0.005359 0.1 -0.164217 0 0 -1.5708</pose>
        <geometry>
          <cylinder>
            <length>0.39572</length>
            <radius>0.0175</radius>
          </cylinder>
        </geometry>
        <surface>
          <contact>
            <ode>
              <kp>1e+06</kp>
              <kd>100</kd>
            </ode>
          </contact>
          <friction>
            <ode>
              <mu>1.85</mu>
              <mu2>1.85</mu2>
            </ode>
          </friction>
        </surface>
      </collision>
      <collision name='LH_SHANK_fixed_joint_lump__LF_FOOT_collision_sensor_collision_3'>
        <pose>0.014109 0.1 -0.362077 0 0 -1.5708</pose>
        <geometry>
          <sphere>
            <radius>0.031455</radius>
          </sphere>
        </geometry>
      </collision>
      <visual name='LH_SHANK_fixed_joint_lump__LH_shank_fixed_visual'>
        <pose>0 0 0 0 -0 1.5708</pose>
        <geometry>
          <mesh>
            <scale>1 1 1</scale>
            <uri>model://ocs2_robotic_assets/resources/anymal_d/meshes/shank_r.dae</uri>
          </mesh>
        </geometry>
      </visual>
      <visual name='LH_SHANK_fixed_joint_lump__LH_FOOT_visual_1'>
        <pose>0.02225 0.1 -0.39246 0 0 -1.5708</pose>
        <geometry>
          <mesh>
            <scale>1 1 1</scale>
            <uri>model://ocs2_robotic_assets/resources/anymal_d/meshes/foot.dae</uri>
          </mesh>
        </geometry>
      </visual>
      <sensor name='lh_foot_contact' type='contact'>
        <plugin name='lh_contact_plugin' filename='libContactSensor.so'/>
        <contact>
          <collision>LH_SHANK_fixed_joint_lump__LH_FOOT_collision_sensor_collision_3</collision>
          <topic>__default_topic__</topic>
        </contact>
        <pose>0.02225 0.1 -0.39246 0 0 -1.5708</pose>
      </sensor>
    </link>
    <joint name='RF_HAA' type='revolute'>
      <pose relative_to='base'>0.304 -0.109 0 0 -0 0</pose>
      <parent>base</parent>
      <child>RF_HIP</child>
      <axis>
        <xyz>1 0 0</xyz>
        <limit>
          <lower>-0.610865</lower>
          <upper>0.785398</upper>
          <effort>80</effort>
          <velocity>8.5</velocity>
        </limit>
        <dynamics>
          <damping>0</damping>
          <friction>0</friction>
          <spring_reference>0</spring_reference>
          <spring_stiffness>0</spring_stiffness>
        </dynamics>
      </axis>
    </joint>
    <link name='RF_HIP'>
      <pose relative_to='RF_HAA'>0 0 0 0 -0 0</pose>
      <inertial>
        <pose>0.035047 0.001227 0 0 -0 0</pose>
        <mass>0.36586</mass>
        <inertia>
          <ixx>0.000238523</ixx>
          <ixy>-3.25536e-06</ixy>
          <ixz>1.268e-08</ixz>
          <iyy>0.000558246</iyy>
          <iyz>-1.811e-08</iyz>
          <izz>0.000443321</izz>
        </inertia>
      </inertial>
      <visual name='RF_HIP_fixed_joint_lump__RF_hip_fixed_visual'>
        <pose>0 0 0 -3.14159 0 0</pose>
        <geometry>
          <mesh>
            <scale>1 1 1</scale>
            <uri>model://ocs2_robotic_assets/resources/anymal_d/meshes/hip.dae</uri>
          </mesh>
        </geometry>
      </visual>
    </link>
    <joint name='RF_HFE' type='revolute'>
      <pose relative_to='RF_HIP'>0.069 -0.006 0 0 -0 1.5708</pose>
      <parent>RF_HIP</parent>
      <child>RF_THIGH</child>
      <axis>
        <xyz>1 0 0</xyz>
        <limit>
          <lower>-9.42478</lower>
          <upper>9.42478</upper>
          <effort>80</effort>
          <velocity>8.5</velocity>
        </limit>
        <dynamics>
          <damping>0</damping>
          <friction>0</friction>
          <spring_reference>0</spring_reference>
          <spring_stiffness>0</spring_stiffness>
        </dynamics>
      </axis>
    </joint>
    <link name='RF_THIGH'>
      <pose relative_to='RF_HFE'>0 0 0 0 -0 0</pose>
      <inertial>
        <pose>-0.090511 8.8e-05 -0.140188 0 -0 0</pose>
        <mass>5.1322</mass>
        <inertia>
          <ixx>0.10488</ixx>
          <ixy>0.000281268</ixy>
          <ixz>-0.0200595</ixz>
          <iyy>0.107959</iyy>
          <iyz>-0.000242195</iyz>
          <izz>0.0139329</izz>
        </inertia>
      </inertial>
      <collision name='RF_THIGH_fixed_joint_lump__RF_HFE_drive_collision'>
        <pose>-0.0595 0 0 0 1.5708 0</pose>
        <geometry>
          <cylinder>
            <length>0.119</length>
            <radius>0.05375</radius>
          </cylinder>
        </geometry>
      </collision>
      <collision name='RF_THIGH_fixed_joint_lump__RF_thigh_fixed_collision_1'>
        <pose>-0.105195 -0 0 1.5708 0 -1.5708</pose>
        <geometry>
          <cylinder>
            <length>0.08313</length>
            <radius>0.07</radius>
          </cylinder>
        </geometry>
      </collision>
      <collision name='RF_THIGH_fixed_joint_lump__RF_thigh_fixed_collision_2'>
        <pose>-0.09513 -0 -0.1425 0 0 -1.5708</pose>
        <geometry>
          <box>
            <size>0.093 0.063 0.285</size>
          </box>
        </geometry>
      </collision>
      <collision name='RF_THIGH_fixed_joint_lump__RF_thigh_fixed_collision_3'>
        <pose>-0.085065 -0 -0.285 1.5708 0 -1.5708</pose>
        <geometry>
          <cylinder>
            <length>0.08313</length>
            <radius>0.07</radius>
          </cylinder>
        </geometry>
      </collision>
      <collision name='RF_THIGH_fixed_joint_lump__RF_KFE_drive_collision_4'>
        <pose>-0.121 -0 -0.285 3.14159 1.5708 0</pose>
        <geometry>
          <cylinder>
            <length>0.119</length>
            <radius>0.05375</radius>
          </cylinder>
        </geometry>
      </collision>
      <visual name='RF_THIGH_fixed_joint_lump__RF_HFE_drive_visual'>
        <pose>0 0 0 0 -0 0</pose>
        <geometry>
          <mesh>
            <scale>1 1 1</scale>
            <uri>model://ocs2_robotic_assets/resources/anymal_d/meshes/drive.dae</uri>
          </mesh>
        </geometry>
      </visual>
      <visual name='RF_THIGH_fixed_joint_lump__RF_thigh_fixed_visual_1'>
        <pose>0 0 0 0 -0 1.5708</pose>
        <geometry>
          <mesh>
            <scale>1 1 1</scale>
            <uri>model://ocs2_robotic_assets/resources/anymal_d/meshes/thigh.dae</uri>
          </mesh>
        </geometry>
      </visual>
      <visual name='RF_THIGH_fixed_joint_lump__RF_KFE_drive_visual_2'>
        <pose>-0.1805 -0 -0.285 0 0 -3.14159</pose>
        <geometry>
          <mesh>
            <scale>1 1 1</scale>
            <uri>model://ocs2_robotic_assets/resources/anymal_d/meshes/drive.dae</uri>
          </mesh>
        </geometry>
      </visual>
    </link>
    <joint name='RF_KFE' type='revolute'>
      <pose relative_to='RF_THIGH'>-0.1805 -0 -0.285 0 0 -3.14159</pose>
      <parent>RF_THIGH</parent>
      <child>RF_SHANK</child>
      <axis>
        <xyz>-1 0 0</xyz>
        <limit>
          <lower>-9.42478</lower>
          <upper>9.42478</upper>
          <effort>80</effort>
          <velocity>8.5</velocity>
        </limit>
        <dynamics>
          <damping>0</damping>
          <friction>0</friction>
          <spring_reference>0</spring_reference>
          <spring_stiffness>0</spring_stiffness>
        </dynamics>
      </axis>
    </joint>
    <link name='RF_SHANK'>
      <pose relative_to='RF_KFE'>0 0 0 0 -0 0</pose>
      <inertial>
        <pose>0.008086 0.050934 -0.090019 0 -0 0</pose>
        <mass>0.79598</mass>
        <inertia>
          <ixx>0.0189109</ixx>
          <ixy>5.43254e-05</ixy>
          <ixz>6.22956e-05</ixz>
          <iyy>0.016665</iyy>
          <iyz>0.00354904</iyz>
          <izz>0.00253121</izz>
        </inertia>
      </inertial>
      <collision name='RF_SHANK_fixed_joint_lump__RF_shank_fixed_collision'>
        <pose>0 0 0 1.5708 -0 1.5708</pose>
        <geometry>
          <cylinder>
            <length>0.05732</length>
            <radius>0.071</radius>
          </cylinder>
        </geometry>
      </collision>
      <collision name='RF_SHANK_fixed_joint_lump__RF_shank_fixed_collision_1'>
        <pose>0 0.066415 0 1.5708 -0 1.5708</pose>
        <geometry>
          <box>
            <size>0.13283 0.08302 0.05732</size>
          </box>
        </geometry>
      </collision>
      <collision name='RF_SHANK_fixed_joint_lump__RF_FOOT_collision_2'>
        <pose>0.005359 0.1 -0.164217 0 -0 1.5708</pose>
        <geometry>
          <cylinder>
            <length>0.39572</length>
            <radius>0.0175</radius>
          </cylinder>
        </geometry>
        <surface>
          <contact>
            <ode>
              <kp>1e+06</kp>
              <kd>100</kd>
            </ode>
          </contact>
          <friction>
            <ode>
              <mu>1.85</mu>
              <mu2>1.85</mu2>
            </ode>
          </friction>
        </surface>
      </collision>
      <collision name='RF_SHANK_fixed_joint_lump__RF_FOOT_collision_sensor_collision_3'>
        <pose>0.014109 0.1 -0.362077 0 -0 1.5708</pose>
        <geometry>
          <sphere>
            <radius>0.031455</radius>
          </sphere>
        </geometry>
        <surface>
          <contact>
            <ode>
              <kp>1e+06</kp>
              <kd>100</kd>
            </ode>
          </contact>
          <friction>
            <ode>
              <mu>1.85</mu>
              <mu2>1.85</mu2>
            </ode>
          </friction>
        </surface>
      </collision>
      <visual name='RF_SHANK_fixed_joint_lump__RF_shank_fixed_visual'>
        <pose>0 0 0 0 -0 1.5708</pose>
        <geometry>
          <mesh>
            <scale>1 1 1</scale>
            <uri>model://ocs2_robotic_assets/resources/anymal_d/meshes/shank_r.dae</uri>
          </mesh>
        </geometry>
      </visual>
      <visual name='RF_SHANK_fixed_joint_lump__RF_FOOT_visual_1'>
        <pose>0.02225 0.1 -0.39246 0 0 -1.5708</pose>
        <geometry>
          <mesh>
            <scale>1 1 1</scale>
            <uri>model://ocs2_robotic_assets/resources/anymal_d/meshes/foot.dae</uri>
          </mesh>
        </geometry>
      </visual>
      <sensor name='rf_foot_contact' type='contact'>
        <plugin name='rf_contact_plugin' filename='libContactSensor.so'/>
        <contact>
          <collision>RF_SHANK_fixed_joint_lump__RF_FOOT_collision_sensor_collision_3</collision>
          <topic>__default_topic__</topic>
        </contact>
        <pose>0.02225 0.1 -0.39246 0 -0 1.5708</pose>
      </sensor>
    </link>
    <joint name='RH_HAA' type='revolute'>
      <pose relative_to='base'>-0.304 -0.109 0 0 0 -3.14159</pose>
      <parent>base</parent>
      <child>RH_HIP</child>
      <axis>
        <xyz>-1 0 0</xyz>
        <limit>
          <lower>-0.610865</lower>
          <upper>0.785398</upper>
          <effort>80</effort>
          <velocity>8.5</velocity>
        </limit>
        <dynamics>
          <damping>0</damping>
          <friction>0</friction>
          <spring_reference>0</spring_reference>
          <spring_stiffness>0</spring_stiffness>
        </dynamics>
      </axis>
    </joint>
    <link name='RH_HIP'>
      <pose relative_to='RH_HAA'>0 0 0 0 -0 0</pose>
      <inertial>
        <pose>0.035047 -0.001227 0 0 -0 0</pose>
        <mass>0.36586</mass>
        <inertia>
          <ixx>0.000238523</ixx>
          <ixy>3.25536e-06</ixy>
          <ixz>1.268e-08</ixz>
          <iyy>0.000558246</iyy>
          <iyz>1.811e-08</iyz>
          <izz>0.000443321</izz>
        </inertia>
      </inertial>
      <visual name='RH_HIP_fixed_joint_lump__RH_hip_fixed_visual'>
        <pose>0 0 0 0 -0 0</pose>
        <geometry>
          <mesh>
            <scale>1 1 1</scale>
            <uri>model://ocs2_robotic_assets/resources/anymal_d/meshes/hip.dae</uri>
          </mesh>
        </geometry>
      </visual>
    </link>
    <joint name='RH_HFE' type='revolute'>
      <pose relative_to='RH_HIP'>0.069 0.006 0 0 0 -1.5708</pose>
      <parent>RH_HIP</parent>
      <child>RH_THIGH</child>
      <axis>
        <xyz>1 0 0</xyz>
        <limit>
          <lower>-9.42478</lower>
          <upper>9.42478</upper>
          <effort>80</effort>
          <velocity>8.5</velocity>
        </limit>
        <dynamics>
          <damping>0</damping>
          <friction>0</friction>
          <spring_reference>0</spring_reference>
          <spring_stiffness>0</spring_stiffness>
        </dynamics>
      </axis>
    </joint>
    <link name='RH_THIGH'>
      <pose relative_to='RH_HFE'>0 0 0 0 -0 0</pose>
      <inertial>
        <pose>-0.090511 -8.8e-05 -0.140188 0 -0 0</pose>
        <mass>5.1322</mass>
        <inertia>
          <ixx>0.10488</ixx>
          <ixy>-0.00014199</ixy>
          <ixz>-0.0200595</ixz>
          <iyy>0.107959</iyy>
          <iyz>0.000403</iyz>
          <izz>0.0139329</izz>
        </inertia>
      </inertial>
      <collision name='RH_THIGH_fixed_joint_lump__RH_HFE_drive_collision'>
        <pose>-0.0595 0 0 0 1.5708 0</pose>
        <geometry>
          <cylinder>
            <length>0.119</length>
            <radius>0.05375</radius>
          </cylinder>
        </geometry>
      </collision>
      <collision name='RH_THIGH_fixed_joint_lump__RH_thigh_fixed_collision_1'>
        <pose>-0.105195 -0 0 1.5708 0 -1.5708</pose>
        <geometry>
          <cylinder>
            <length>0.08313</length>
            <radius>0.07</radius>
          </cylinder>
        </geometry>
      </collision>
      <collision name='RH_THIGH_fixed_joint_lump__RH_thigh_fixed_collision_2'>
        <pose>-0.09513 -0 -0.1425 0 0 -1.5708</pose>
        <geometry>
          <box>
            <size>0.093 0.063 0.285</size>
          </box>
        </geometry>
      </collision>
      <collision name='RH_THIGH_fixed_joint_lump__RH_thigh_fixed_collision_3'>
        <pose>-0.085065 -0 -0.285 1.5708 0 -1.5708</pose>
        <geometry>
          <cylinder>
            <length>0.08313</length>
            <radius>0.07</radius>
          </cylinder>
        </geometry>
      </collision>
      <collision name='RH_THIGH_fixed_joint_lump__RH_KFE_drive_collision_4'>
        <pose>-0.121 -0 -0.285 3.14159 1.5708 0</pose>
        <geometry>
          <cylinder>
            <length>0.119</length>
            <radius>0.05375</radius>
          </cylinder>
        </geometry>
      </collision>
      <visual name='RH_THIGH_fixed_joint_lump__RH_HFE_drive_visual'>
        <pose>0 0 0 0 -0 0</pose>
        <geometry>
          <mesh>
            <scale>1 1 1</scale>
            <uri>model://ocs2_robotic_assets/resources/anymal_d/meshes/drive.dae</uri>
          </mesh>
        </geometry>
      </visual>
      <visual name='RH_THIGH_fixed_joint_lump__RH_thigh_fixed_visual_1'>
        <pose>0 0 0 0 -0 1.5708</pose>
        <geometry>
          <mesh>
            <scale>1 1 1</scale>
            <uri>model://ocs2_robotic_assets/resources/anymal_d/meshes/thigh.dae</uri>
          </mesh>
        </geometry>
      </visual>
      <visual name='RH_THIGH_fixed_joint_lump__RH_KFE_drive_visual_2'>
        <pose>-0.1805 -0 -0.285 0 0 -3.14159</pose>
        <geometry>
          <mesh>
            <scale>1 1 1</scale>
            <uri>model://ocs2_robotic_assets/resources/anymal_d/meshes/drive.dae</uri>
          </mesh>
        </geometry>
      </visual>
    </link>
    <joint name='RH_KFE' type='revolute'>
      <pose relative_to='RH_THIGH'>-0.1805 -0 -0.285 0 0 -3.14159</pose>
      <parent>RH_THIGH</parent>
      <child>RH_SHANK</child>
      <axis>
        <xyz>-1 0 0</xyz>
        <limit>
          <lower>-9.42478</lower>
          <upper>9.42478</upper>
          <effort>80</effort>
          <velocity>8.5</velocity>
        </limit>
        <dynamics>
          <damping>0</damping>
          <friction>0</friction>
          <spring_reference>0</spring_reference>
          <spring_stiffness>0</spring_stiffness>
        </dynamics>
      </axis>
    </joint>
    <link name='RH_SHANK'>
      <pose relative_to='RH_KFE'>0 0 0 0 -0 0</pose>
      <inertial>
        <pose>0.008086 -0.050934 -0.090019 0 -0 0</pose>
        <mass>0.79598</mass>
        <inertia>
          <ixx>0.0189109</ixx>
          <ixy>-5.43254e-05</ixy>
          <ixz>6.22956e-05</ixz>
          <iyy>0.016665</iyy>
          <iyz>-0.00354904</iyz>
          <izz>0.00253121</izz>
        </inertia>
      </inertial>
      <collision name='RH_SHANK_fixed_joint_lump__RH_shank_fixed_collision'>
        <pose>0 0 0 1.5708 -0 1.5708</pose>
        <geometry>
          <cylinder>
            <length>0.05732</length>
            <radius>0.071</radius>
          </cylinder>
        </geometry>
      </collision>
      <collision name='RH_SHANK_fixed_joint_lump__RH_shank_fixed_collision_1'>
        <pose>-0 -0.066415 0 1.5708 -0 1.5708</pose>
        <geometry>
          <box>
            <size>0.13283 0.08302 0.05732</size>
          </box>
        </geometry>
      </collision>
      <collision name='RH_SHANK_fixed_joint_lump__RH_FOOT_collision_2'>
        <pose>0.005359 -0.1 -0.164217 0 -0 1.5708</pose>
        <geometry>
          <cylinder>
            <length>0.39572</length>
            <radius>0.0175</radius>
          </cylinder>
        </geometry>
        <surface>
          <contact>
            <ode>
              <kp>1e+06</kp>
              <kd>100</kd>
            </ode>
          </contact>
          <friction>
            <ode>
              <mu>1.85</mu>
              <mu2>1.85</mu2>
            </ode>
          </friction>
        </surface>
      </collision>
      <collision name='RH_SHANK_fixed_joint_lump__RF_FOOT_collision_sensor_collision_3'>
        <pose>0.014109 -0.1 -0.362077 0 -0 1.5708</pose>
        <geometry>
          <sphere>
            <radius>0.031455</radius>
          </sphere>
        </geometry>
      </collision>
      <visual name='RH_SHANK_fixed_joint_lump__RH_shank_fixed_visual'>
        <pose>0 0 0 0 0 -1.5708</pose>
        <geometry>
          <mesh>
            <scale>1 1 1</scale>
            <uri>model://ocs2_robotic_assets/resources/anymal_d/meshes/shank_l.dae</uri>
          </mesh>
        </geometry>
      </visual>
      <visual name='RH_SHANK_fixed_joint_lump__RH_FOOT_visual_1'>
        <pose>0.02225 -0.1 -0.39246 0 0 -1.5708</pose>
        <geometry>
          <mesh>
            <scale>1 1 1</scale>
            <uri>model://ocs2_robotic_assets/resources/anymal_d/meshes/foot.dae</uri>
          </mesh>
        </geometry>
      </visual>
      <sensor name='rh_foot_contact' type='contact'>
        <plugin name='rh_contact_plugin' filename='libContactSensor.so'/>
        <contact>
          <collision>RH_SHANK_fixed_joint_lump__RH_FOOT_collision_sensor_collision_3</collision>
          <topic>__default_topic__</topic>
        </contact>
        <pose>0.02225 -0.1 -0.39246 0 -0 1.5708</pose>
      </sensor>
    </link>
    <plugin name='gazebo_ros_control' filename='libgazebo_ros_control.so'>
      <robotSimType>gazebo_ros_control/DefaultRobotHWSim</robotSimType>
      <robotNamespace>/anymal_d</robotNamespace>
    </plugin>
    <static>0</static>
    <plugin name='RobotStatePublisher' filename='/home/kuba/Documents/ros/devel/.private/tbai_ros_gazebo/lib/libRobotStatePublisher.so'/>
  </model>
</sdf>
